Workbook
Name \a: #REF!
Name \a: #REF!
Name \D: #REF!
Name \D: #REF!
Name \E: #REF!
Name \E: #REF!
Name \G: #REF!
Name \G: #REF!
Name \I: #REF!
Name \I: #REF!
Name \P: #REF!
Name \P: #REF!
Name \R: #REF!
Name \R: #REF!
Name \S: #REF!
Name \S: #REF!
Name _BLANK_B1..B16_: #REF!
Name _BLANK_B1..B16_: #REF!
Name _CALC__: #REF!
Name _CALC__: #REF!
Name _GOTO_D1_: #REF!
Name _GOTO_D1_: #REF!
Name _MENU_: #REF!
Name _MENU_: #REF!
Name _MENUBRANCH_MEN: #REF!
Name _MENUBRANCH_MEN: #REF!
Name A_CLEAR: #REF!
Name A_CLEAR: #REF!
Name AccTrim: [1]INITIAL!$F$16
Name Acd: [1]INITIAL!$F$12
Name APPTRIM: [1]INITIAL!$D$16
Name B_次画面: #REF!
Name B_次画面: #REF!
Name C_計算: #REF!
Name C_計算: #REF!
Name CORR1: [1]INITIAL!$D$35
Name DAP: [1]INITIAL!$S$15
Name DBM: [1]INITIAL!$S$17
Name DENSITY: [1]INITIAL!$I$6
Name DFP: [1]INITIAL!$S$11
Name disp: #REF!
Name DISPL: [1]INITIAL!$D$29
Name dMdZ: [1]INITIAL!$D$32
Name DMP: [1]INITIAL!$S$13
Name Fcd: [1]INITIAL!$F$8
Name Hydro: [2]Hydrostatics!$A$2:$E$77
Name K: [3]Inputs!$G$17
Name LBP: [2]Inputs!$C$12
Name LCF: [1]INITIAL!$D$30
Name LCG_Table: #REF!
Name LCG_Table: #REF!
Name MEANDRAFT: [1]INITIAL!$I$8
Name MEANOFMEAN: [1]INITIAL!$I$15
Name MENU: #REF!
Name MENU: #REF!
Name MIDSHIPDRAFT: [1]INITIAL!$I$10
Name P_印刷: #REF!
Name P_印刷: #REF!
Name PRINT_AREA_MI: #REF!
Name PRINT_AREA_MI: #REF!

Sheet initial
B2: INITIAL SURVEY
E3: Port: | F3: PORT WALCOTT, AUS | H3: Date: | I3: 45181
C4: 1 | E4: Voy. No: | F4: 102A
C5: LOAD=1 DISCH=2 | G5: Actual Sea Water Density | I5: 1.023
C6: 8.13 | E6: 8.1
G7: Fuel Oil | I7: 1293.87
C8: =IF(C11>E11,ABS(DEGREES(ATAN((C11-E11)/data!$E$14))),"") -> 0.10051881 | E8: =IF(E11>C11,ABS(DEGREES(ATAN((C11-E11)/data!$E$14))),"") | G8: Diesel Oil | I8: 67.34
C9: =IF(C11>E11,"List to Port","") -> List to Port | E9: =IF(E11>C11,"List to Starboard","") | G9: Fresh Water | I9: 215
G10: Ballast | I10: 99020
C11: 9.18 | E11: 9.08 | G11: Others | I11: 0
G12: =IF($C$4=1,"","Constant")
G13: =IF(C4=1,"Constant","Cargo") -> Constant | I13: =calc!F36 -> 629
G15: =IF(C4=1,"Required Constant","") -> Required Constant | I15: 629
C16: 9.86 | E16: 9.8 | G16: =IF(C4=1,"Required Ballast","") -> Required Ballast | I16: =IF(I15=0,"",calc!H32) -> 99020
C18: =CONCATENATE(ROUND(calc!G13,1),calc!H13) -> 12.5cm SAG
C19: =CONCATENATE(ROUND(calc!D13,2),calc!E13) -> 1.8m by the stern | G19: =IF(C4=2,"BL QUANTITY","") | I19: 247974
C23: Mean Mid | D23: =calc!F16 -> 9.13 | E23: dØ | G23: =IF(C4=2,"DIFFERENCE","") | I23: =I13-I19 -> -247345
C24: Mean draft (corr) | D24: =calc!F17 -> 9.0051627 | E24: dM
C25: Mean of Mean | D25: =calc!F18 -> 9.0675813 | E25: Av=(dØ+dM)/2
C26: Quarter Mean | D26: =calc!F19 -> 9.0987907 | E26: dAv=(dØx3+dM)/4
C27: Displacement | D27: =calc!F26 -> 134548 | E27: MT
C29: REMARKS:
C31: Sea Condition: | D31: Moderate | E31: Swell: | F31: Moderate | G31: Others:
C32: Survey Commenced | D32: 45181.438 | G32: =IF(initial!C4=1, "Commenced Loading", "Commenced Discharging") -> Commenced Loading | H32: 45181.455
C33: Completed | D33: 45181.451
C36: - NON CARGO WEIGHTS SUMMARY-
C37: FPT | D37: 1880 | G37: FWT P | H37: 50
C38: WBT 1 P | D38: 1963 | G38: FWT S | H38: 50
C39: WBT 1S | D39: 1963 | G39: DW S | H39: 40
C40: WBT 2P | D40: 2542 | G40: TOTAL FW | H40: =SUM(H37:I39) -> 140
C41: WBT 2S | D41: 2542 | G41: 1 FOT P | H41: 385
C42: WBT 3 P | D42: 5245 | G42: 1FOT S | H42: 386.4
C43: WBT 3S | D43: 5245 | G43: 2FOT P
C44: WBT 4P | D44: 5100 | G44: 2FOT S
C45: WBT 4S | D45: 5100 | G45: SET/SERV
C46: WBT 5P | D46: 1286 | G46: TOTAL FO | H46: =SUM(H41:I45) -> 771.4
C47: WBT 5S | D47: 1286 | G47: 1DOTS | H47: 36.1
C48: APT | D48: 709 | G48: 2DOTS | H48: 30
C49: DWST P/S | D49: 0 | G49: SET SERV
C50: TTL m3 | D50: =SUM(D37:E49) -> 34861 | G50: TOTAL DO | H50: =SUM(H47:I49) -> 66.1
...

Sheet interim
E1: DRAFT MARK DISTANCE | H1: 2
B2: INTERIM SURVEY | E2: REMARKS: | F2: TRIMMING
E3: Port: | F3: =initial!F3 -> PORT WALCOTT, AUS | H3: Date: | I3: 45182
E4: Voy. No: | F4: =initial!F4 -> 102A
G5: Actual Sea Water Density | I5: 1.023
C6: 17.78 | E6: 17.78
G7: Fuel Oil | I7: 1282.37
C8: =IF(C11>E11,ABS(DEGREES(ATAN((C11-E11)/data!$E$14))),"") | E8: =IF(E11>C11,ABS(DEGREES(ATAN((C11-E11)/data!$E$14))),"") | G8: Diesel Oil | I8: 67.33
C9: =IF(C11>E11,"List to Port","") | E9: =IF(E11>C11,"List to Starboard","") | G9: Fresh Water | I9: 202
G10: Ballast | I10: 31
C11: 17.74 | E11: 17.74 | G11: Others | I11: 0
G12: Constant | I12: =initial!I15 -> 629
G14: Cargo Onboard | I14: =calc!M36 -> 242951
G15: =IF(initial!C4=1,"Total to Load","Total to Disch") -> Total to Load | I15: 234100
C16: 17.67 | E16: 17.67 | G16: =IF(initial!C4=1,"Cargo to Load","Cargo Discharged") -> Cargo to Load | I16: =I15-I14 -> -8851
E17: .
C18: =CONCATENATE(ROUND(calc!N13,1),calc!O13) -> 1.7cm SAG
C19: =CONCATENATE(ROUND(calc!K13,2),calc!L13) -> -0.12m by the head
C23: Mean Mid | D23: =calc!M16 -> 17.739784 | E23: dØ | G23: Shore figure | H23: 206087
C24: Mean draft (corr) | D24: =calc!M17 -> 17.722905 | E24: dM | G24: Ship's figure | H24: =I14 -> 242951
C25: Mean of Mean | D25: =calc!M18 -> 17.731345 | E25: Av=(dØ+dM)/2 | G25: Belt error | H25: =ABS((H24-H23)/H24) -> 0.1517343 | I25: =IF(H23>H24,"Less Onboard","More Onboard") -> More Onboard
C26: Quarter Mean | D26: =calc!M19 -> 17.735564 | E26: dAv=(dØx3+dM)/4
C27: Displacement | D27: =calc!M26 -> 278486 | E27: MT | G27: Difference | H27: =H24-H23 -> 36864
C29: REMARKS: | D29: FINAL MSD declared at 18.12m
C31: Sea Condition: | D31: Calm | E31: Swell: | F31: Low Swell | G31: Others:
C32: Survey Commenced | D32: 45182.66 | G32: =IF(initial!C4=1, "Commenced Loading", "Commenced Discharging") -> Commenced Loading | H32: =initial!H32 -> 45181.455
C33: Completed | D33: 45182.671
C36: - NON CARGO WEIGHTS SUMMARY-
C37: FPT | D37: 4 | G37: FWT P
C38: WBT 1 P | D38: 9 | G38: FWT S
C39: WBT 1S | D39: 9 | G39: DW S
C40: WBT 2P | D40: 82 | G40: TOTAL FW | H40: =SUM(H37:I39) -> 0
C41: WBT 2S | D41: 24 | G41: 1 FOT P
C42: WBT 3 P | D42: 213 | G42: 1FOT S
C43: WBT 3S | D43: 91 | G43: 2FOT P
C44: WBT 4P | D44: 93 | G44: 2FOT S
C45: WBT 4S | D45: 103 | G45: SET/SERV
C46: WBT 5P | D46: 8 | G46: TOTAL FO | H46: =SUM(H41:I45) -> 0
C47: WBT 5S | D47: 5 | G47: 1DOTS
C48: APT | D48: 3 | G48: 2DOTS
...

Sheet trimming
B2: Interim Draft at Perpendiculars | E2: FWD | F2: MID | G2: AFT | P2: Hatch | Q2: LCG
E3: =calc!K11 -> 17.780629 | F3: =calc!M11 -> 17.739784 | G3: =calc!O11 -> 17.665181 | L3: Interim Survey | P3: 1 | Q3: =data!N22 -> -121.07
K4: Shore figure | L4: =interim!H23 -> 206087 | M4: MT | P4: 2 | Q4: =data!N23 -> -88.9 | X4: =(1+(calc!M25-1.023)/1.023) -> 1
B5: TRIMMING BY DRAFT | P5: 3 | Q5: =data!N24 -> -64.15
K6: Ship's figure | L6: =calc!M36 -> 242951 | M6: MT | P6: 4 | Q6: =data!N25 -> -34.45 | V6: DRAFT | W6: DISP | X6: TPC | Y6: LCF | Z6: MCTC
B7: Req'd Departure Trim | E7: 5 | F7: cm | P7: 5 | Q7: =data!N26 -> -9.7 | V7: =VLOOKUP(V15,hydro!$B$3:$F$78,1) -> 17.8 | W7: =VLOOKUP(V7,hydro!$B$3:$F$78,2) -> 280143 | X7: =VLOOKUP(V7,hydro!$B$3:$F$78,3) -> 173.1 | Y7: =VLOOKUP(V7,hydro!$B$3:$F$78,4) -> -0.16 | Z7: =VLOOKUP(V7,hydro!$B$3:$F$78,5) -> 4037.2
K8: Belt error | L8: =ABS((L6-L4)/L6) -> 0.1517343 | M8: =IF(L4>L6,"Less Onboard","More Onboard") -> More Onboard | P8: 6 | Q8: =data!N27 -> 20 | V8: =V15 -> 17.904892 | W8: =(W9-W7)/($V$9-$V$7)*($V$8-$V$7)+W7 -> 281959.73 | X8: =(X9-X7)/($V$9-$V$7)*($V$8-$V$7)+X7 -> 173.25734 | Y8: =(Y9-Y7)/($V$9-$V$7)*($V$8-$V$7)+Y7 -> -0.02888487 | Z8: =(Z9-Z7)/($V$9-$V$7)*($V$8-$V$7)+Z7 -> 4048.2137 | AA8: by draft
B9: Req'd Departure Draft | E9: 18.07 | F9: m | J9: Formula: (ship fig-shore fig) ÷ ship fig x 100 | P9: 7 | Q9: =data!N28 -> 44.75 | V9: =V7+0.2 -> 18 | W9: =VLOOKUP(V9,hydro!$B$3:$F$78,2) -> 283607 | X9: =VLOOKUP(V9,hydro!$B$3:$F$78,3) -> 173.4 | Y9: =VLOOKUP(V9,hydro!$B$3:$F$78,4) -> 0.09 | Z9: =VLOOKUP(V9,hydro!$B$3:$F$78,5) -> 4058.2
P10: 8 | Q10: =data!N29 -> 74.45 | V10: =VLOOKUP(V11,hydro!$B$3:$F$78,1) -> 17.8 | W10: =VLOOKUP(V10,hydro!$B$3:$F$78,2) -> 280143 | X10: =VLOOKUP(V10,hydro!$B$3:$F$78,3) -> 173.1 | Y10: =VLOOKUP(V10,hydro!$B$3:$F$78,4) -> -0.16 | Z10: =VLOOKUP(V10,hydro!$B$3:$F$78,5) -> 4037.2
B11: sinkage req'd | E11: =(E9-F3)*100 -> 33.021579 | F11: cm | P11: 9 | Q11: =data!N30 -> 99.2 | V11: =V30 -> 17.879952 | W11: =(calc!D50-calc!D48)/(calc!C50-calc!C48)*(V11-calc!C48)+calc!D48 -> 281525.37 | X11: =(calc!E50-calc!E48)/(calc!C50-calc!C48)*(V11-calc!C48)+calc!E48 -> 173.2599 | Y11: =(calc!F50-calc!F48)/(calc!C50-calc!C48)*(V11-calc!C48)+calc!F48 -> -0.056062259 | Z11: =(calc!H50-calc!H48)/(calc!C50-calc!C48)*(V11-calc!C48)+calc!H48 -> 4046.0347 | AA11: by cargo
B12: Remaining Cargo | D12: =V17 -> 5721 | F12: With Belt Error Corr. | V12: =V10+0.2 -> 18 | W12: =VLOOKUP(V12,hydro!$B$3:$F$78,2) -> 283607 | X12: =VLOOKUP(V12,hydro!$B$3:$F$78,3) -> 173.4 | Y12: =VLOOKUP(V12,hydro!$B$3:$F$78,4) -> 0.09 | Z12: =VLOOKUP(V12,hydro!$B$3:$F$78,5) -> 4058.2
F13: CARGO TO ORDER | J13: TRIMMING BY CARGO REQUESTED | U13: by draft
E14: LCG | F14: CARGO | G14: LESS | H14: MORE | U14: sinkage | V14: =E11 -> 33.021579 | Y14: df | Z14: da | AA14: mid
B15: Trimming Hatch | D15: 1 | E15: =VLOOKUP(D15,P3:Q11,2) -> -121.07 | F15: =W23 -> 1837 | G15: =(F15*$L$8)+F15 -> 2115.7359 | H15: =F15-(F15*$L$8) -> 1558.2641 | J15: Remaining Cargo | L15: =IF(E9=0,D26,D12) -> 5721 | N15: CARGO ORDERED | U15: half draft | V15: =(F3+E9)/2 -> 17.904892 | Y15: =(1/X8+(data!E13/2+Y8)*((Y8-E15)/(Z8*data!E13)))*100 -> 2.0719012 | Z15: =(1/X8-(data!E13/2-Y8)*((Y8-E15)/(Z8*data!E13)))*100 -> -0.91808707 | AB15: fwd hatch per 100T
D16: 8 | E16: =VLOOKUP(D16,P3:Q11,2) -> 74.45 | F16: =W24 -> 3884 | G16: =(F16*$L$8)+F16 -> 4473.336 | H16: =F16-(F16*$L$8) -> 3294.664 | K16: LCG | L16: CARGO | N16: LESS | O16: MORE | P16: Requested | U16: TPC | V16: =X8 -> 173.25734 | Y16: =(1/X8+(data!E13/2+Y8)*((Y8-E16)/(Z8*data!E13)))*100 -> -0.34255646 | Z16: =(1/X8-(data!E13/2-Y8)*((Y8-E16)/(Z8*data!E13)))*100 -> 1.4972398 | AB16: aft hatch per 100T
J17: 1 | K17: =VLOOKUP(J17,P3:Q11,2) -> -121.07 | L17: 1835 | N17: =P17-(P17*$L$8) -> 0 | O17: =(P17*$L$8)+P17 -> 0 | U17: Cargo | V17: =ROUND(V16*V14,0) -> 5721 | Y17: =E3 -> 17.780629 | Z17: =G3 -> 17.665181 | AA17: =(Y17+Z17)/2 -> 17.722905
D18: FWD | E18: MID | F18: AFT | G18: TRIM | J18: 2 | K18: =VLOOKUP(J18,P3:Q11,2) -> -88.9 | N18: =P18-(P18*$L$8) -> 0 | O18: =(P18*$L$8)+P18 -> 0 | U18: =IF(F3>AA17,"current sag","current hog") -> current sag | V18: =F3-AA17 -> 0.016879189 | Y18: =W24*Y16/10000 -> -0.13304893 | Z18: =W24*Z16/10000 -> 0.58152795 | AB18: =CONCATENATE("load in hatch # ",D16) -> load in hatch # 8
D19: =Y22 -> 18.028461 | E19: =AA22 -> 18.070002 | F19: =Z22 -> 18.075986 | G19: =F19-D19 -> 0.047525078 | J19: 5 | K19: =VLOOKUP(J19,P3:Q11,2) -> -9.7 | N19: =P19-(P19*$L$8) -> 0 | O19: =(P19*$L$8)+P19 -> 0 | U19: present trim | V19: =(G3-E3)*100 -> -11.544875 | Y19: =Y17+Y18 -> 17.64758 | Z19: =Z17+Z18 -> 18.246709 | AA19: =(Y19+Z19)/2 -> 17.947145
B20: Est. total cargo after trimming = | E20: =L6+D12 -> 248672 | J20: 8 | K20: =VLOOKUP(J20,P3:Q11,2) -> 74.45 | L20: 3890 | N20: =P20-(P20*$L$8) -> 0 | O20: =(P20*$L$8)+P20 -> 0 | U20: req'd trim | V20: =E7 -> 5 | Y20: =W23*Y15/10000 -> 0.38060826 | Z20: =W23*Z15/10000 -> -0.16865259 | AB20: =CONCATENATE("load in hatch # ",D15) -> load in hatch # 1
J21: 9 | K21: =VLOOKUP(J21,P3:Q11,2) -> 99.2 | N21: =P21-(P21*$L$8) -> 0 | O21: =(P21*$L$8)+P21 -> 0 | U21: COT | V21: =V20-V19 -> 16.544875 | Y21: =Y19+Y20 -> 18.028189 | Z21: =Z19+Z20 -> 18.078056 | AA21: =(Y21+Z21)/2 -> 18.053122
B22: TRIMMING BY CARGO | J22: TOTAL REQUEST | L22: =SUM(L17:L21) -> 5725 | U22: x + y = | V22: =V17/100 -> 57.21 | W22: =V21-V23 -> 187.60211 | Y22: =Y21+($Z$21-$Y$21)*data!O13/data!E13 -> 18.028461 | Z22: =Z21-($Z$21-$Y$22)*data!O15/data!E13 -> 18.075986 | AA22: =AA21+V18 -> 18.070002 | AB22: drafts at perpendicular
J23: Present S.G. | L23: =calc!M25 -> 1.023 | N23: FWD | O23: MID | P23: AFT | Q23: TRIM | V23: =(Z15-Y15)*V22 -> -171.05723 | W23: =V17-W24 -> 1837 | X23: fwd hatch
J24: Draft at Perpendicular after Loading | N24: =IF(AND(L17=0,L18=0,L19=0,L20=0,L21=0),IF(E9>0,Y22,Y36),Y49) -> 18.027797 | O24: =IF(AND(L17=0,L18=0,L19=0,L20=0),IF(E9>0,AA22,AA36),AA49) -> 18.070129 | P24: =IF(AND(L17=0,L18=0,L19=0,L20=0),IF(E9>0,Z22,Z36),Z49) -> 18.076845 | Q24: =P24-N24 -> 0.049047836 | V24: =(Z16-Y16)-(Z15-Y15) -> 4.8297846 | W24: =ROUND(W22/V24*100,0) -> 3884 | X24: aft hatch
B25: Req'd total cargo | D25: 247800 | F25: With Belt Error Corr.
B26: Remaining Cargo | D26: =D25-calc!M36 -> 4849 | F26: CARGO TO ORDER | J26: Est. total cargo after trimming = | M26: =L6+SUM(L17:L21) -> 248676
E27: LCG | F27: CARGO | G27: LESS | H27: MORE | U27: by cargo
B28: Trimming Hatch | D28: 1 | E28: =VLOOKUP(D28,P3:Q11,2) -> -121.07 | F28: =ROUND(W37,0) -> 1505 | G28: =(F28*$L$8)+F28 -> 1733.3601 | H28: =F28-(F28*$L$8) -> 1276.6399 | J28: Arrival S.G. | L28: 1.023 | N28: FWD | O28: MID | P28: AFT | Q28: TRIM | U28: present mid | V28: =F3 -> 17.739784 | Y28: df | Z28: da | AA28: mid
D29: 8 | E29: =VLOOKUP(D29,P3:Q11,2) -> 74.45 | F29: =ROUND(W38,0) -> 3344 | G29: =(F29*$L$8)+F29 -> 3851.3995 | H29: =F29-(F29*$L$8) -> 2836.6005 | J29: Draft at Perpendicular Arrival Port | N29: =W54 -> 18.024069 | O29: =X54 -> 18.060608 | P29: =Y54 -> 18.061532 | Q29: =Z54 -> 0.037462922 | U29: final mid | V29: =V28+D26/V31/100 -> 18.02012 | Y29: =(1/X11+(data!E13/2+Y11)*((Y11-E28)/(Z11*data!E13)))*100 -> 2.0721086 | Z29: =(1/X11-(data!E13/2-Y11)*((Y11-E28)/(Z11*data!E13)))*100 -> -0.9188182 | AB29: fwd hatch per 100T
U30: half mid | V30: =(V28+V29)/2 -> 17.879952 | Y30: =(1/X11+(data!E13/2+Y11)*((Y11-E29)/(Z11*data!E13)))*100 -> -0.34324021 | Z30: =(1/X11-(data!E13/2-Y11)*((Y11-E29)/(Z11*data!E13)))*100 -> 1.4982186 | AB30: aft hatch per 100T
D31: FWD | E31: MID | F31: AFT | G31: TRIM | U31: TPC | V31: =calc!E49 -> 172.97113 | Y31: =E3 -> 17.780629 | Z31: =G3 -> 17.665181 | AA31: =(Y31+Z31)/2 -> 17.722905
D32: =Y36 -> 17.978075 | E32: =AA36 -> 18.019682 | F32: =Z36 -> 18.025727 | G32: =F32-D32 -> 0.047651566 | U32: Cargo | V32: =D26 -> 4849 | Y32: =W38*Y30/10000 -> -0.11476528 | Z32: =W38*Z30/10000 -> 0.50094211 | AB32: =CONCATENATE("load in hatch # ",D29) -> load in hatch # 8
U33: present trim | V33: =(G3-E3)*100 -> -11.544875 | Y33: =Y31+Y32 -> 17.665864 | Z33: =Z31+Z32 -> 18.166123 | AA33: =(Y33+Z33)/2 -> 17.915993
U34: req'd trim | V34: =E7 -> 5 | Y34: =W37*Y29/10000 -> 0.31193836 | Z34: =W37*Z29/10000 -> -0.13832028 | AB34: =CONCATENATE("load in hatch # ",D28) -> load in hatch # 1
B35: ARRIVAL DRAFT CALCULATION | U35: COT | V35: =V34-V33 -> 16.544875 | Y35: =Y33+Y34 -> 17.977802 | Z35: =Z33+Z34 -> 18.027802 | AA35: =(Y35+Z35)/2 -> 18.002802
U36: x + y = | V36: =V32/100 -> 48.49 | W36: =V35-V37 -> 161.57492 | Y36: =Y35+($Z$35-$Y$35)*data!$O$13/data!$E$13 -> 17.978075 | Z36: =Z35-(Z35-Y36)*data!$O$15/data!$E$13 -> 18.025727 | AA36: =AA35+V18 -> 18.019682 | AB36: drafts at perpendicular
V37: =(Z29-Y29)*V36 -> -145.03004 | W37: =V32-W38 -> 1505.4151 | X37: fwd hatch
B38: Tanks | D38: LCG | F38: Present R.O.B. | H38: Arrival R.O.B. | K38: Present | L38: Arrival | M38: DIFFERENCE | O38: REMARKS | V38: =(Z30-Y30)-(Z29-Y29) -> 4.8323856 | W38: =W36/V38*100 -> 3343.5849 | X38: aft hatch
B39: =data!H7 -> 1 FOT PORT | D39: =data!J7 -> 106.32 | F39: 321 | H39: 1 | J39: Total FO | K39: =SUM(F39:G46)-F41 -> 1028 | L39: =SUM(H39:I46)-H41 -> 598 | M39: =L39-K39 -> -430 | O39: CONSUMPTION
B40: =data!H8 -> 1 FOT STBD | D40: =data!J8 -> 106.32 | F40: 626 | H40: 516 | U40: by ordered cargo
B41: =data!H9 -> 2 FOT PORT | D41: =data!J9 -> 128.36 | F41: 143 | H41: 143 | J41: Total FW | K41: =SUM(F49:G50) -> 190 | L41: =SUM(H49:I50) -> 280 | M41: =L41-K41 -> 90 | O41: ADJUSTMENT TO MINIMUM | U41: present mid | V41: =F3 -> 17.739784 | Y41: df | Z41: da | AA41: mid
...

Sheet final
E1: DRAFT MARK DISTANCE | H1: 2
B2: FINAL SURVEY
E3: Port: | F3: =initial!F3 -> PORT WALCOTT, AUS | H3: Date: | I3: 45182
E4: Voy. No: | F4: =initial!F4 -> 102A
G5: Actual Sea Water Density | I5: 1.023
C6: 18.04 | E6: 18.04
C7: . | G7: Fuel Oil | I7: 1282.37
C8: =IF(C11>E11,ABS(DEGREES(ATAN((C11-E11)/data!$E$14))),"") | E8: =IF(E11>C11,ABS(DEGREES(ATAN((C11-E11)/data!$E$14))),"") | G8: Diesel Oil | I8: 67.33
C9: =IF(C11>E11,"List to Port","") | E9: =IF(E11>C11,"List to Starboard","") | G9: Fresh Water | I9: 202
G10: Ballast | I10: 31
C11: 18.05 | E11: 18.05 | G11: Others | I11: 0
G12: Constant | I12: =initial!I15 -> 629
G14: Cargo Onboard | I14: =calc!T36 -> 248432.4
G15: =IF(initial!C4=1,"Total to Load","Total to Disch") -> Total to Load | I15: 247640
C16: 18.08 | E16: 18.08 | G16: Difference | I16: =I14-I15 -> 792.40313
C18: =CONCATENATE(ROUND(calc!U13,1),calc!V13) -> 1.1cm HOG
C19: =CONCATENATE(ROUND(calc!R13,2),calc!S13) -> 0.04m by the stern
C23: Mean Mid | D23: =calc!T16 -> 18.050078 | E23: dØ | G23: Shore figure | H23: 223343
C24: Mean draft (corr) | D24: =calc!T17 -> 18.060762 | E24: dM | G24: Ship's figure | H24: =I14 -> 248432.4
C25: Mean of Mean | D25: =calc!T18 -> 18.05542 | E25: Av=(dØ+dM)/2 | G25: Belt error | H25: =ABS((H24-H23)/H24) -> 0.10099086 | I25: =IF(H23>H24,"Less Onboard","More Onboard") -> More Onboard
C26: Quarter Mean | D26: =calc!T19 -> 18.052749 | E26: dAv=(dØx3+dM)/4
C27: Displacement | D27: =calc!T26 -> 283967.4 | E27: MT | G27: Difference | H27: =H24-H23 -> 25089.403
C29: REMARKS: | D29: Cargo Quantity as per BL 247,974 MT
D30: Cargo is 229MT more than BL
C31: Sea Condition: | D31: Moderate | E31: Swell: | F31: Moderate | G31: Others:
G32: =IF(initial!C4=1, "Commenced Loading", "Commenced Discharging") -> Commenced Loading | H32: =interim!H32 -> 45181.455
C33: Final Survey Completed | D33: 45182.705 | G33: =IF(initial!C4=1, "Completed Loading", "Completed Discharging") -> Completed Loading | H33: 45182.697
C36: - NON CARGO WEIGHTS SUMMARY-
C37: FPT | D37: 4 | G37: FWT P | H37: 35
C38: WBT 1 P | D38: 4 | G38: FWT S | H38: 55
C39: WBT 1S | D39: 6 | G39: DW S | H39: 55
C40: WBT 2P | D40: 6 | G40: TOTAL FW | H40: =SUM(H37:I39) -> 145
C41: WBT 2S | D41: 4 | G41: 1 FOT P | H41: 325
C42: WBT 3 P | D42: 5 | G42: 1FOT S | H42: 414
C43: WBT 3S | D43: 4 | G43: 2FOT P | H43: 0
C44: WBT 4P | D44: 6 | G44: 2FOT S | H44: 0
C45: WBT 4S | D45: 5 | G45: SET/SERV | H45: 28
C46: WBT 5P | D46: 4 | G46: TOTAL FO | H46: =SUM(H41:I45) -> 767
C47: WBT 5S | D47: 5 | G47: 1DOTS | H47: 31
C48: APT | D48: 1 | G48: 2DOTS | H48: 31
...

Sheet report
B2: DRAFT SURVEY REPORT
B4: Ships Name | F4: =data!E2 -> WARRAMBOO
B5: Gross Tonnage | F5: =data!E7 -> 132512
B6: Port of Registry | F6: =data!E6 -> TOKYO
B7: Summer Draft | F7: =data!E9 -> 18.025
B8: Yoyage Number | F8: =initial!F4 -> 102A
B9: Load Port | F9: PORT WALCOTT, AUSTRALIA
B10: Discharge Port | F10: QINGDAO & LANSHAN
B11: Cargo | F11: PB FINES & PB LUMPS
B13: Initial Survey Completed | F13: =initial!D33 -> 45181.451
B14: =IF(initial!C4=1, "Commenced Loading", "Commenced Discharging") -> Commenced Loading | F14: =final!H32 -> 45181.455
B15: =IF(initial!C4=1, "Completed Loading", "Completed Discharging") -> Completed Loading | F15: =final!H33 -> 45182.697
B16: Final Survey Completed | F16: =final!D33 -> 45182.705
G18: INITIAL | I18: FINAL
B19: DRAUGHTS (meters)
B20: Forward Mean | G20: =calc!D11 -> 8.1051872 | I20: =calc!R11 -> 18.039771
B21: Aft Mean | G21: =calc!H11 -> 9.9051381 | I21: =calc!V11 -> 18.081752
B22: Fore & Aft Mean | G22: =calc!F12 -> 9.0051627 | I22: =calc!T12 -> 18.060762
B23: Mean Midships | G23: =calc!F16 -> 9.13 | I23: =calc!T16 -> 18.050078
B24: Mean of Means | G24: =calc!F18 -> 9.0675813 | I24: =calc!T18 -> 18.05542
B25: Double Means of Means | G25: =calc!F19 -> 9.0987907 | I25: =calc!T19 -> 18.052749
B27: Density (kg/l) | G27: =calc!F25 -> 1.023 | I27: =calc!T25 -> 1.023
B29: Displacement
B30: From Vessel's Scale | G30: =calc!F21 -> 135863.34 | I30: =calc!T21 -> 284522.2
B31: Corrected for Trim | G31: =calc!F23 -> 134811 | I31: =calc!T23 -> 284522.57
B32: Corrected for Density | G32: =calc!F26 -> 134548 | I32: =calc!T26 -> 283967.4
B34: Known Weights
B35: Bunkers FO & DO | G35: =calc!F30 -> 1361 | I35: =calc!T30 -> 1350
B36: Fresh Water | G36: =calc!F31 -> 215 | I36: =calc!T31 -> 202
B37: Ballast | G37: =calc!F32 -> 99020 | I37: =calc!T32 -> 31
B38: Others | G38: =calc!F33 -> 0 | I38: =calc!T33 -> 0
B39: =IF(initial!C4,"Constant","Constant") -> Constant | G39: =calc!F34 -> 0 | I39: =calc!T34 -> 629
B41: Corrected Displacement | G41: =calc!F26 -> 134548 | I41: =calc!T26 -> 283967.4
B42: Light Ship | G42: =calc!F27 -> 33323 | I42: =calc!T27 -> 33323
B43: Deadweight | G43: =calc!F28 -> 101225 | I43: =calc!T28 -> 250644.4
B44: Total Known Weights | G44: =SUM(G35:G39) -> 100596 | I44: =SUM(I35:I39) -> 2212
B46: =IF(initial!C4=1,"Initial Constant","Initial Cargo") -> Initial Constant | G46: =G43-G44 -> 629
B47: =IF(initial!C4=1,"Final Cargo Qty Loaded","Cargo Qty Remain after Discharging") -> Final Cargo Qty Loaded | I47: =I43-I44 -> 248432.4
B49: From the figures obtained by means of the draught marks checked at the initial and final surveys, I hereby certify the weight of the cargo which was loaded on vessel to be as follows:
B52: =IF(initial!C4=1,"CARGO LOADED IN MT","CARGO REMAIN IN MT") -> CARGO LOADED IN MT | D52: =I47 -> 248432.4 | G52: EQUIVALENT TO | I52: =D52*0.98420653 -> 244508.79
...

Sheet Hatch
C3: HATCH BREAKDOWN / STOWAGE SUMMARY
C4: SEQUENCE: ALL FINES | K4: MSD | L4: 18.025 | N4: VOY NO. | O4: 102A | Q4: LOAD PORT | S4: PORT WALCOTT | W4: REVISION
C5: POUR | D5: HATCH | E5: PLANNED TONNES | F5: PLAN | G5: ACTUAL BELT TONNES | H5: ACTUAL | I5: DIFF | K5: HATCH | L5: TOTAL PLANNED | M5: TTL SHORE FIGURE | N5: DRAFT SURVEY FIGURE | O5: FINAL DRAFT SURVEY FIGURE AS PER BL | P5: Max. Allowable Wt | R5: PLANNED TANK TOP ALLOWANCE | T5: SHORE FIGURE TANK TOP ALLOWANCE | V5: DRAFT SURVEY TANK TOP ALLOWANCE | X5: ACTUAL FILL % | Y5: STOWAGE FACTOR (M3/MT) | Z5: GRADE | AB5: HATCH CAPACITY | AC5: MAX CAPACITY BY SF | AE5: S/F Conversion Table
F6: SUBTOTAL | H6: SUBTOTAL | P6: HATCH | Q6: HOLD | AE6: CF/LT | AG6: CF/MT | AI6: m3/MT | AK6: MT/m3
C7: 1 | D7: 5 | E7: 18700 | F7: =E7 -> 18700 | G7: 18706 | H7: =G7 -> 18706 | I7: =G7-E7 -> 6 | K7: 1 | L7: =SUMIF($D$7:$D$27,K7,$E$7:$E$27) -> 38235 | M7: =SUMIF($D$7:$D$27,K7,$G$7:$G$27) -> 38307 | N7: =IF(M7="","",ROUND(($N$16/$M$16)*M7,0)) -> 38140 | O7: =N7 -> 38140 | P7: 35235 | Q7: 35235 | R7: =P7-L7 -> -3000 | S7: =P7-L7 -> -3000 | T7: =P7-M7 -> -3072 | U7: =Q7-M7 -> -3072 | V7: =P7-N7 -> -2905 | W7: =Q7-N7 -> -2905 | X7: =(O7/AC7)*100 -> 76.842698 | Y7: 0.44 | Z7: PBF | AB7: =data!O22 -> 21838.9 | AC7: =AB7/Y7 -> 49633.864 | AE7: 42.5 | AG7: =IF(AE7="","",AE7/AI13) -> 41.830709 | AI7: =IF(AE7="","",AE7/AI12) -> 1.1848341 | AK7: =IF(AE7="","",1/AI7) -> 0.844
C8: 2 | D8: 1 | E8: 16000 | F8: =SUM(E7:E8) -> 34700 | G8: 16015 | H8: =SUM(G7:G8) -> 34721 | I8: =G8-E8 -> 15 | K8: 2 | L8: =SUMIF($D$7:$D$27,K8,$E$7:$E$27) -> 27300 | M8: =SUMIF($D$7:$D$27,K8,$G$7:$G$27) -> 27292 | N8: =IF(M8="","",ROUND(($N$16/$M$16)*M8,0)) -> 27173 | O8: =N8 -> 27173 | P8: 24150 | Q8: 48301 | R8: =P8-L8 -> -3150 | S8: =Q8-(L8+L9) -> -5439 | T8: =P8-M8 -> -3142 | U8: =Q8-(M8+M9) -> -5443 | V8: =P8-N8 -> -3023 | W8: =Q8-(N8+N9) -> -5209 | X8: =(O8/AC8)*100 -> 76.496256 | Y8: 0.5 | Z8: PBL | AB8: =data!O23 -> 17761 | AC8: =AB8/Y8 -> 35522 | AE8: =IF(AG8="","",AG8*AI13) -> 43.18 | AG8: 42.5 | AI8: =IF(AG8="","",AE8/AI12) -> 1.2037915 | AK8: =IF(AG8="","",1/AI8) -> 0.83070866
C9: 3 | D9: 8 | E9: 17000 | F9: =SUM(E7:E9) -> 51700 | G9: 17012 | H9: =SUM(G7:G9) -> 51733 | I9: =G9-E9 -> 12 | K9: 3 | L9: =SUMIF($D$7:$D$27,K9,$E$7:$E$27) -> 26440 | M9: =SUMIF($D$7:$D$27,K9,$G$7:$G$27) -> 26452 | N9: =IF(M9="","",ROUND(($N$16/$M$16)*M9,0)) -> 26337 | O9: =N9 -> 26337 | P9: 24150 | R9: =P9-L9 -> -2290 | T9: =P9-M9 -> -2302 | V9: =P9-N9 -> -2187 | X9: =(O9/AC9)*100 -> 74.142785 | Y9: 0.5 | Z9: PBL | AB9: =data!O24 -> 17761 | AC9: =AB9/Y9 -> 35522 | AE9: =IF(AI9="","",AI9*AI12) -> 15.7828 | AG9: =IF(AI9="","",AE9/AI13) -> 15.534252 | AI9: 0.44 | AK9: =IF(AI9="","",1/AI9) -> 2.2727273
C10: 4 | D10: 4 | E10: 15000 | F10: =SUM(E7:E10) -> 66700 | G10: 15004 | H10: =SUM(G7:G10) -> 66737 | I10: =G10-E10 -> 4 | K10: 4 | L10: =SUMIF($D$7:$D$27,K10,$E$7:$E$27) -> 25000 | M10: =SUMIF($D$7:$D$27,K10,$G$7:$G$27) -> 25015 | N10: =IF(M10="","",ROUND(($N$16/$M$16)*M10,0)) -> 24906 | O10: =N10 -> 24906 | P10: 24141 | Q10: =P10+P11 -> 48282 | R10: =P10-L10 -> -859 | S10: =Q10-(L10+L11) -> 282 | T10: =P10-M10 -> -874 | U10: =Q10-(M10+M11) -> 252 | V10: =P10-N10 -> -765 | W10: =Q10-(N10+N11) -> 461 | X10: =(O10/AC10)*100 -> 61.724907 | Y10: 0.44 | Z10: PBF | AB10: =data!O25 -> 17754 | AC10: =AB10/Y10 -> 40350 | AE10: =IF(AK10="","",AI12*AI10) -> 42.002342 | AG10: =IF(AK10="","",AE10/AI13) -> 41.340888 | AI10: =IF(AK10="","",1/AK10) -> 1.1709602 | AK10: 0.854
C11: 5 | D11: 9 | E11: 13000 | F11: =SUM(E7:E11) -> 79700 | G11: 13011 | H11: =SUM(G7:G11) -> 79748 | I11: =G11-E11 -> 11 | K11: 5 | L11: =SUMIF($D$7:$D$27,K11,$E$7:$E$27) -> 23000 | M11: =SUMIF($D$7:$D$27,K11,$G$7:$G$27) -> 23015 | N11: =IF(M11="","",ROUND(($N$16/$M$16)*M11,0)) -> 22915 | O11: =N11 -> 22915 | P11: 24141 | R11: =P11-L11 -> 1141 | T11: =P11-M11 -> 1126 | V11: =P11-N11 -> 1226 | X11: =(O11/AC11)*100 -> 56.790582 | Y11: 0.44 | Z11: PBF | AB11: =data!O26 -> 17754 | AC11: =AB11/Y11 -> 40350
C12: 6 | D12: 3 | E12: 26440 | F12: =SUM(E7:E12) -> 106140 | G12: 26452 | H12: =SUM(G7:G12) -> 106200 | I12: =G12-E12 -> 12 | K12: 6 | L12: =SUMIF($D$7:$D$27,K12,$E$7:$E$27) -> 26700 | M12: =SUMIF($D$7:$D$27,K12,$G$7:$G$27) -> 26691 | N12: =IF(M12="","",ROUND(($N$16/$M$16)*M12,0)) -> 26575 | O12: =N12 -> 26575 | P12: 24152 | Q12: 48305 | R12: =P12-L12 -> -2548 | S12: =Q12-(L12+L13) -> -5595 | T12: =P12-M12 -> -2539 | U12: =Q12-(M12+M13) -> -5599 | V12: =P12-N12 -> -2423 | W12: =Q12-(N12+N13) -> -5364 | X12: =(O12/AC12)*100 -> 74.817005 | Y12: 0.5 | Z12: PBL | AB12: =data!O27 -> 17760 | AC12: =AB12/Y12 -> 35520 | AE12: 1m3/MT | AH12: = | AI12: 35.87 | AK12: CF/LT
C13: 7 | D13: 6 | E13: 26700 | F13: =SUM(E7:E13) -> 132840 | G13: 26691 | H13: =SUM(G7:G13) -> 132891 | I13: =G13-E13 -> -9 | K13: 7 | L13: =SUMIF($D$7:$D$27,K13,$E$7:$E$27) -> 27200 | M13: =SUMIF($D$7:$D$27,K13,$G$7:$G$27) -> 27213 | N13: =IF(M13="","",ROUND(($N$16/$M$16)*M13,0)) -> 27094 | O13: =N13 -> 27094 | P13: 24152 | R13: =P13-L13 -> -3048 | T13: =P13-M13 -> -3061 | V13: =P13-N13 -> -2942 | X13: =(O13/AC13)*100 -> 76.278153 | Y13: 0.5 | Z13: PBL | AB13: =data!O28 -> 17760 | AC13: =AB13/Y13 -> 35520 | AE13: 1LT | AH13: = | AI13: 1.016 | AK13: MT
C14: 8 | D14: 7 | E14: 10000 | F14: =SUM(E7:E14) -> 142840 | G14: 10013 | H14: =SUM(G7:G14) -> 142904 | I14: =G14-E14 -> 13 | K14: 8 | L14: =SUMIF($D$7:$D$27,K14,$E$7:$E$27) -> 28390 | M14: =SUMIF($D$7:$D$27,K14,$G$7:$G$27) -> 28417 | N14: =IF(M14="","",ROUND(($N$16/$M$16)*M14,0)) -> 28293 | O14: =N14 -> 28293 | P14: 24712 | Q14: 49423 | R14: =P14-L14 -> -3678 | S14: =Q14-(L14+L15) -> -6067 | T14: =P14-M14 -> -3705 | U14: =Q14-(M14+M15) -> -6111 | V14: =P14-N14 -> -3581 | W14: =Q14-(N14+N15) -> -5869 | X14: =(O14/AC14)*100 -> 68.445788 | Y14: 0.44 | Z14: PBF | AB14: =data!O29 -> 18188 | AC14: =AB14/Y14 -> 41336.364
C15: 9 | D15: 2 | E15: 27300 | F15: =SUM(E7:E15) -> 170140 | G15: 27292 | H15: =SUM(G7:G15) -> 170196 | I15: =G15-E15 -> -8 | K15: 9 | L15: =SUMIF($D$7:$D$27,K15,$E$7:$E$27) -> 27100 | M15: =SUMIF($D$7:$D$27,K15,$G$7:$G$27) -> 27117 | N15: =IF(M15="","",ROUND(($N$16/$M$16)*M15,0)) -> 26999 | O15: =N15 -> 26999 | P15: 24712 | R15: =P15-L15 -> -2388 | T15: =P15-M15 -> -2405 | V15: =P15-N15 -> -2287 | X15: =(O15/AC15)*100 -> 65.315373 | Y15: 0.44 | Z15: PBF | AB15: =data!O30 -> 18188 | AC15: =AB15/Y15 -> 41336.364
C16: 10 | D16: 7 | E16: 17200 | F16: =SUM(E7:E16) -> 187340 | G16: 17200 | H16: =SUM(G7:G16) -> 187396 | I16: =G16-E16 -> 0 | K16: TOTAL | L16: =SUM(L7:L15) -> 249365 | M16: =SUM(M7:M15) -> 249519 | N16: =M18 -> 248432 | O16: =SUM(O7:O15) -> 248432
C17: 11 | D17: 9 | E17: 14100 | F17: =SUM(E7:E17) -> 201440 | G17: 14106 | H17: =SUM(G7:G17) -> 201502 | I17: =G17-E17 -> 6 | K17: SHORE FIGURE | M17: =M16 -> 249519 | P17: Shore Figure Error/Belt Error | R17: =$N$16-$M$16 -> -1087 | T17: =($M$16-$N$16)/$M$16 -> 0.0043563817 | V17: =IF($R$17>0,"MORE CARGO ON BOARD","LESS CARGO ON BOARD") -> LESS CARGO ON BOARD
C18: 12 | D18: 1 | E18: 10000 | F18: =SUM(E7:E18) -> 211440 | G18: 10010 | H18: =SUM(G7:G18) -> 211512 | I18: =G18-E18 -> 10 | K18: DRAFT SURVEY FIGURE | M18: 248432
C19: 13 | D19: 5 | E19: 4300 | F19: =SUM(E7:E19) -> 215740 | G19: 4309 | H19: =SUM(G7:G19) -> 215821 | I19: =G19-E19 -> 9
C20: 14 | D20: 8 | E20: 7500 | F20: =SUM(E7:E20) -> 223240 | G20: 7510 | H20: =SUM(G7:G20) -> 223331 | I20: =G20-E20 -> 10 | K20: GRADE | M20: REQUIRED | O20: PLUS 10% | P20: MINUS 10% | Q20: PLANNED TONNES | S20: SHORE FIGURE TONNES | U20: DRAFT SURVEY TONNES | W20: DIFFERENCE FROM PLANNED - DRAFT SURVEY | Y20: REMARKS
C21: 15 | D21: 1 | E21: 10400 | F21: =SUM(E7:E21) -> 233640 | G21: 10410 | H21: =SUM(G7:G21) -> 233741 | I21: =G21-E21 -> 10 | K21: PBF | M21: 135000 | O21: =M21+AA21 -> 148500 | P21: =M21-AA21 -> 121500 | Q21: =SUMIF($Z$7:$Z$15,K21,$L$7:$L$15) -> 141725 | R21: =(Q21/M21)*100 -> 104.98148 | S21: =SUMIF($Z$7:$Z$15,K21,$M$7:$M$15) -> 141871 | T21: =(S21/M21)*100 -> 105.08963 | U21: =SUMIF($Z$7:$Z$15,K21,$O$7:$O$15) -> 141253 | V21: =(U21/M21)*100 -> 104.63185 | W21: =U21-Q21 -> -472 | Y21: =IF(U21>=O21,"OVER CONTRACT",IF(U21<=P21,"LESS CONTRACT","WITH IN CONTRACT QTY")) -> WITH IN CONTRACT QTY | AA21: =M21*0.1 -> 13500
C22: 16 | D22: 4 | E22: 10000 | F22: =SUM(E7:E22) -> 243640 | G22: 10011 | H22: =SUM(G7:G22) -> 243752 | I22: =G22-E22 -> 11 | K22: PBL | M22: 100000 | O22: =M22+AA22 -> 110000 | P22: =M22-AA22 -> 90000 | Q22: =SUMIF($Z$7:$Z$15,K22,$L$7:$L$15) -> 107640 | R22: =(Q22/M22)*100 -> 107.64 | S22: =SUMIF($Z$7:$Z$15,K22,$M$7:$M$15) -> 107648 | T22: =(S22/M22)*100 -> 107.648 | U22: =SUMIF($Z$7:$Z$15,K22,$O$7:$O$15) -> 107179 | V22: =(U22/M22)*100 -> 107.179 | W22: =U22-Q22 -> -461 | Y22: =IF(U22>=O22,"OVER CONTRACT",IF(U22<=P22,"LESS CONTRACT","WITH IN CONTRACT QTY")) -> WITH IN CONTRACT QTY | AA22: =M22*0.1 -> 10000
C23: 17 | D23: 8 | E23: 3890 | F23: =SUM(E7:E23) -> 247530 | G23: 3895 | H23: =SUM(G7:G23) -> 247647 | I23: =G23-E23 -> 5 | AA23: =M23*0.1 -> 0
C24: 18 | D24: 1 | E24: 1835 | F24: =SUM(E7:E24) -> 249365 | G24: 1872 | H24: =SUM(G7:G24) -> 249519 | I24: =G24-E24 -> 37 | AA24: =M24*0.1 -> 0
C25: 19 | I25: =G25-E25 -> 0 | K25: TOTAL | M25: =SUM(M21:N24) -> 235000 | O25: =SUM(O21:O24) -> 258500 | P25: =SUM(P21:P24) -> 211500 | Q25: =SUM(Q21:Q24) -> 249365 | R25: =(Q25/M25)*100 -> 106.11277 | S25: =SUM(S21:S24) -> 249519 | T25: =(S25/M25)*100 -> 106.1783 | U25: =SUM(U21:U24) -> 248432 | V25: =(U25/M25)*100 -> 105.71574
C26: 20 | I26: =G26-E26 -> 0 | K26: REMARKS | M26: FINAL MSD declared at 18.025m
C28: TOTAL | E28: =SUM(E7:E26) -> 249365 | G28: =SUM(G7:G26) -> 249519 | I28: =SUM(I7:I26) -> 154
E29: TOTAL TO GO | G29: =E28-G28 -> -154

Sheet STOW PLAN
B3: M.V. WARRAMBOO
B4: TOKYO
B5: VOY NO.: | E5: =initial!F4 -> 102A | AB5: LOADING PORT: | AG5: PORT WALCOTT, AUS
B6: DATE: | E6: 45153 | AB6: DISCHARGING PORT: | AG6: MAIN CHINESE PORT
B8: STOWAGE PLAN
G13: 9 | J13: 8 | M13: 7 | P13: 6 | S13: 5 | V13: 4 | Y13: 3 | AB13: 2 | AE13: 1
O15: 16300
F16: =Hatch!O15 -> 26999 | I16: =Hatch!O14 -> 28293 | L16: =Hatch!O13 -> 27094 | O16: =Hatch!O12 -> 26575 | R16: =Hatch!O11 -> 22915 | U16: =Hatch!O10 -> 24906 | Y16: =Hatch!O9 -> 26337 | AB16: =Hatch!O8 -> 27173 | AE16: =Hatch!O7 -> 38140
F18: =Hatch!Z15 -> PBF | I18: =Hatch!Z14 -> PBF | L18: =Hatch!Z13 -> PBL | O18: =Hatch!Z12 -> PBL | R18: =Hatch!Z11 -> PBF | U18: =Hatch!Z10 -> PBF | Y18: =Hatch!Z9 -> PBL | AB18: =Hatch!Z8 -> PBL | AE18: =Hatch!Z7 -> PBF
AH19: Total:
AH20: =SUM(F16:AG16) -> 248432 | AN20: `
E25: Grade | N25: QUANTITY
C27: Pilbara Blend Fines | N27: =Hatch!U21 -> 141253
C28: Pilbara Blend Lumps | N28: =Hatch!U22 -> 107179
H30: TOTAL: | P30: =SUM(N27:W29) -> 248432
Z37: Capt. Antonio G. Bracamonte
AA38: Master

Sheet LIST
B2: FINDING DRAFT @ CERTAIN LIST
E3: STARBOARD SIDE ALONGSIDE
C4: LIST | D4: S | E4: 0.12 | F4: DEG | J4: =TAN(RADIANS(E4))*E7 -> 0.1130975 | L4: =J4*100 -> 11.30975 | N4: =ROUND(L4,0) -> 11 | O4: =D4 -> S
D5: =D4 -> S | E5: =J4 -> 0.1130975 | F5: M | J5: =J4*E7 -> 6.107265
C7: BREADTH | D7: = | E7: 54 | F7: mtrs
F9: DRAFT
E10: PORT | G10: STBD
C11: Fwd | D11: = | E11: =O11 -> 9.317 | G11: 9.35 | J11: 0.3 | L11: =(N$4*J11)/100 -> 0.033 | N11: =G11-L11 -> 9.317 | O11: =IF(D$4="S",G11-L11,G11+L11) -> 9.317
C12: Mid | D12: = | E12: =O12 -> 9.66 | G12: 9.77 | J12: =N4 -> 11 | L12: =J12/100 -> 0.11 | N12: =G12-L12 -> 9.66 | O12: =IF(D$4="S",G12-L12,G12+L12) -> 9.66
C13: Aft | D13: = | E13: =O13 -> 10.004 | G13: 10.07 | J13: 0.6 | L13: =(N$4*J13)/100 -> 0.066 | N13: =G13-L13 -> 10.004 | O13: =IF(D$4="S",G13-L13,G13+L13) -> 10.004
E15: PORT SIDE ALONGSIDE
C16: LIST | D16: P | E16: 0.29 | F16: DEG | J16: =TAN(RADIANS(E16))*E19 -> 0.27332089 | L16: =J16*100 -> 27.332089 | N16: =ROUND(L16,0) -> 27 | O16: =D16 -> P
D17: =D16 -> P | E17: =J16 -> 0.27332089 | F17: M | J17: =J16*E19 -> 14.759328
C19: BREADTH | D19: = | E19: 54 | F19: mtrs
F21: DRAFT
E22: PORT | G22: STBD
C23: Fwd | D23: = | E23: 8.86 | G23: =O23 -> 8.779 | J23: 0.3 | L23: =(N$16*J23)/100 -> 0.081 | N23: =G23-L23 -> 8.698 | O23: =IF(D$16="P",E23-L23,E23+L23) -> 8.779
C24: Mid | D24: = | E24: 9.73 | G24: =O24 -> 9.46 | J24: =N16 -> 27 | L24: =J24/100 -> 0.27 | N24: =G24-L24 -> 9.19 | O24: =IF(D$16="P",E24-L24,E24+L24) -> 9.46
C25: Aft | D25: = | E25: 10.28 | G25: =O25 -> 10.118 | J25: 0.6 | L25: =(N$16*J25)/100 -> 0.162 | N25: =G25-L25 -> 9.956 | O25: =IF(D$16="P",E25-L25,E25+L25) -> 10.118

Sheet density
C2: CHANGE OF DRAFT/TRIM DUE TO DENSITY
C4: DENSITY
C5: OLD DENSITY | E5: 1.023
C6: NEW DENSITY | E6: 1.025
C8: DRAFT | G8: FINAL DRAFT W/DENSITY CORR
C9: FWD | D9: 18.1 | G9: FWD | H9: =ROUND(IF(E5>E6,D9+C15+E15,D9-C15-E15),3) -> 18.06
C10: AFT | D10: 18.12 | G10: AFT | H10: =ROUND(IF(E5>E6,D10+C15-E15,D10-C15+E15),3) -> 18.094
C11: MID | D11: 18.12 | G11: MID | H11: =ROUND(IF(E5>E6,D11+C15,D11-C15),3) -> 18.087
C12: TRIM | D12: =D10-D9 -> 0.02 | E12: =IF(D12>0,"by the stern","by the head") -> by the stern | G12: TRIM | H12: =H10-H9 -> 0.034 | I12: =IF(H12>0,"by the stern","by the head") -> by the stern
C13: M OF M | D13: =(6*D11+D10+D9)/8 -> 18.1175 | G13: MEAN | H13: =(6*H11+H10+H9)/8 -> 18.0845
C14: DRAFT CHANGE | E14: TRIM CHANGE
C15: =((ABS(E5-E6)*D18)/E18)/100 -> 0.032924129 | E15: =(((D18*ABS(E5-E6)*ABS(H18-F18))/G18/100/2)) -> 0.0072213754
C16: DRAFT | D16: DISP. | E16: TPC | F16: LCF | G16: MTC | H16: LCB
C17: =VLOOKUP(D11,hydro!$B$3:$F$78,1) -> 18 | D17: =VLOOKUP(C17,hydro!$B$3:$F$78,2) -> 283607 | E17: =VLOOKUP(C17,hydro!$B$3:$F$78,3) -> 173.4 | F17: =VLOOKUP(C17,hydro!$B$3:$F$78,4) -> 0.09 | G17: =VLOOKUP(C17,hydro!$B$3:$F$78,5) -> 4058.2 | H17: =VLOOKUP(C17,hydro!$B$3:$G$78,6) -> -10.14
C18: =D13 -> 18.1175 | D18: =(D19-D17)/(C19-C17)*(C18-C17)+D17 -> 285645.62 | E18: =(E19-E17)/(C19-C17)*(C18-C17)+E17 -> 173.5175 | F18: =(F19-F17)/(C19-C17)*(C18-C17)+F17 -> 0.225125 | G18: =(G19-G17)/(C19-C17)*(C18-C17)+G17 -> 4069.7737 | H18: =(H19-H17)/(C19-C17)*(C18-C17)+H17 -> -10.063625
C19: =C17+0.2000000001 -> 18.2 | D19: =VLOOKUP(C19,hydro!$B$3:$F$78,2) -> 287077 | E19: =VLOOKUP(C19,hydro!$B$3:$F$78,3) -> 173.6 | F19: =VLOOKUP(C19,hydro!$B$3:$F$78,4) -> 0.32 | G19: =VLOOKUP(C19,hydro!$B$3:$F$78,5) -> 4077.9 | H19: =VLOOKUP(C19,hydro!$B$3:$G$78,6) -> -10.01

Sheet LOAD RATE
B1: WARRAMBOO - HATCH BREAKDOWN CALCULATION
B3: Date/Time: | D3: 45181.455 | G3: VOYAGE No.: | J3: 102A | L3: PORT: | N3: PORT WALCOTT, AUSTRALIA | Q3: PLANNED MSD: | T3: 18.025
B5: CARGO | C5: SHORE SCALE FIGURE | L5: ACTUAL ALLOWANCE | N5: 10% MOLOO | Q5: Max Tank Strenght 100% | S5: PLANNED ALLOWANCE | U5: Cargo Grade
B6: HOLD | C6: 1st pass | D6: 2nd pass | E6: 3rd pass | F6: TRIMMING QTY | G6: Additional | H6: REMARKS | I6: TOTAL | K6: TO GO | L6: COMBINED | M6: PER HOLD | N6: Order | O6: Min. | P6: Max | S6: COMBINED | T6: PER HOLD
B7: 1 | C7: 16015 | D7: 10010 | E7: 10410 | I7: =SUM(C7:G7) -> 36435 | K7: =N7-I7 -> 1965 | L7: =R7-I7 -> 2775 | M7: =Q7-I7 -> 2775 | N7: 38400 | O7: =N7-(N7*0.1) -> 34560 | P7: =N7+(N7*0.1) -> 42240 | Q7: 39210 | R7: =Q7 -> 39210 | S7: =Q7-N7 -> 810 | T7: =Q7-N7 -> 810 | U7: PBF
B8: 2 | C8: 27292 | I8: =SUM(C8:G8) -> 27292 | K8: =N8-I8 -> 8 | L8: =R8-(I8+I9) -> 2180 | M8: =Q8-I8 -> 670 | N8: 27300 | O8: =N8-(N8*0.1) -> 24570 | P8: =N8+(N8*0.1) -> 30030 | Q8: 27962 | R8: =Q8+Q9 -> 55924 | S8: =R8-(N8+N9) -> 2184 | T8: =Q8-N8 -> 662 | U8: PBL
B9: 3 | C9: 26452 | I9: =SUM(C9:G9) -> 26452 | K9: =N9-I9 -> -12 | M9: =Q9-I9 -> 1510 | N9: 26440 | O9: =N9-(N9*0.1) -> 23796 | P9: =N9+(N9*0.1) -> 29084 | Q9: 27962 | T9: =Q9-N9 -> 1522 | U9: PBL
B10: 4 | C10: 15004 | D10: 10011 | I10: =SUM(C10:G10) -> 25015 | K10: =N10-I10 -> -15 | L10: =R10-(I10+I11) -> 7873 | M10: =Q10-I10 -> 2936.5 | N10: 25000 | O10: =N10-(N10*0.1) -> 22500 | P10: =N10+(N10*0.1) -> 27500 | Q10: 27951.5 | R10: =Q10+Q11 -> 55903 | S10: =R10-(N10+N11) -> 7903 | T10: =Q10-N10 -> 2951.5 | U10: PBF
B11: 5 | C11: 18706 | D11: 4309 | I11: =SUM(C11:G11) -> 23015 | K11: =N11-I11 -> -15 | M11: =Q11-I11 -> 4936.5 | N11: 23000 | O11: =N11-(N11*0.1) -> 20700 | P11: =N11+(N11*0.1) -> 25300 | Q11: 27951.5 | T11: =Q11-N11 -> 4951.5 | U11: PBF
B12: 6 | C12: 26691 | I12: =SUM(C12:G12) -> 26691 | K12: =N12-I12 -> 9 | L12: =R12-(I12+I13) -> 2019 | M12: =Q12-I12 -> 1270.5 | N12: 26700 | O12: =N12-(N12*0.1) -> 24030 | P12: =N12+(N12*0.1) -> 29370 | Q12: 27961.5 | R12: =Q12+Q13 -> 55923 | S12: =R12-(N12+N13) -> 2023 | T12: =Q12-N12 -> 1261.5 | U12: PBL
B13: 7 | C13: 10013 | D13: 17200 | I13: =SUM(C13:G13) -> 27213 | K13: =N13-I13 -> -13 | M13: =Q13-I13 -> 748.5 | N13: 27200 | O13: =N13-(N13*0.1) -> 24480 | P13: =N13+(N13*0.1) -> 29920 | Q13: 27961.5 | T13: =Q13-N13 -> 761.5 | U13: PBL
B14: 8 | C14: 17012 | D14: 7510 | F14: 3895 | I14: =SUM(C14:G14) -> 28417 | K14: =N14-I14 -> -1917 | L14: =R14-(I14+I15) -> 1741 | M14: =Q14-I14 -> 220.5 | N14: 26500 | O14: =N14-(N14*0.1) -> 23850 | P14: =N14+(N14*0.1) -> 29150 | Q14: 28637.5 | R14: =Q14+Q15 -> 57275 | S14: =R14-(N14+N15) -> 3675 | T14: =Q14-N14 -> 2137.5 | U14: PBF
B15: 9 | C15: 13011 | D15: 14106 | I15: =SUM(C15:G15) -> 27117 | K15: =N15-I15 -> -17 | M15: =Q15-I15 -> 1520.5 | N15: 27100 | O15: =N15-(N15*0.1) -> 24390 | P15: =N15+(N15*0.1) -> 29810 | Q15: 28637.5 | T15: =Q15-N15 -> 1537.5 | U15: PBF
B16: TOTAL | C16: =SUM(C7:C15) -> 170196 | D16: =SUM(D7:D15) -> 63146 | E16: =SUM(E7:E15) -> 10410 | F16: =SUM(F7:F15) -> 3895 | G16: =SUM(G7:G15) -> 0 | H16: TOTAL | I16: =SUM(I7:I15) -> 247647 | K16: =SUM(K7:K15) -> -7 | L16: TOTAL ORDER QTY | N16: =SUM(N7:N15) -> 247640 | O16: =SUM(O7:O15) -> 222876 | P16: =SUM(P7:P15) -> 272404
B18: Remarks: | N18: Total Planned | Q18: =N16 -> 247640
N19: Estimate Rate | Q19: 10000
N20: Estimate Load/Disch Time | Q20: =(Q18/Q19)/24 -> 1.0318333
N21: Date/Time Started | Q21: 45181.455
N22: Estimate Completion | Q22: =Q21+Q20 -> 45182.487
N23: Date/Time Now | Q23: 45182.62
N24: Total Figure | Q24: =I16 -> 247647
N25: Remaining | Q25: =N16-Q24 -> -7
N26: Total Work Hours | Q26: =Q23-Q21 -> 1.1652778
N27: Actual Rate | Q27: =((Q24/(Q26-(Q28/24))/24)) -> 8855.0775
N28: Total Stoppage Hours | Q28: 0
N29: Hours to go | Q29: =(Q25/Q27)/24 -> -3.2937788e-05
N30: Estimate Completion

Sheet calc
D2: INITIAL | K2: INTERIM | R2: FINAL
B3: Measured Draft | D3: Fore | F3: Midship | H3: Aft | K3: Fore | M3: Midship | O3: Aft | R3: Fore | T3: Midship | V3: Aft
B4: Starboard | D4: =initial!E6 -> 8.1 | F4: =initial!E11 -> 9.08 | H4: =initial!E16 -> 9.8 | K4: =interim!E6 -> 17.78 | M4: =interim!E11 -> 17.74 | O4: =interim!E16 -> 17.67 | R4: =final!E6 -> 18.04 | T4: =final!E11 -> 18.05 | V4: =final!E16 -> 18.08
B5: Port | D5: =initial!C6 -> 8.13 | F5: =initial!C11 -> 9.18 | H5: =initial!C16 -> 9.86 | K5: =interim!C6 -> 17.78 | M5: =interim!C11 -> 17.74 | O5: =interim!C16 -> 17.67 | R5: =final!C6 -> 18.04 | T5: =final!C11 -> 18.05 | V5: =final!C16 -> 18.08
B6: Mean | C6: dF= | D6: =(D5+D4)/2 -> 8.115 | E6: dØ= | F6: =(F5+F4)/2 -> 9.13 | G6: dA= | H6: =(H5+H4)/2 -> 9.83 | J6: dF= | K6: =(K5+K4)/2 -> 17.78 | L6: dØ= | M6: =(M5+M4)/2 -> 17.74 | N6: dA= | O6: =(O5+O4)/2 -> 17.67 | Q6: dF= | R6: =(R5+R4)/2 -> 18.04 | S6: dØ= | T6: =(T5+T4)/2 -> 18.05 | U6: dA= | V6: =(V5+V4)/2 -> 18.08
C7: App. Trim | D7: =H6-D6 -> 1.715 | F7: =ABS(DEGREES(ATAN((F5-F4)/data!$E$14))) -> 0.10051881 | G7: =IF(F5=F4,"",IF(F5>F4,"List to Port","List to Starboard")) -> List to Port | J7: App. Trim | K7: =O6-K6 -> -0.11 | M7: =ABS(DEGREES(ATAN((M5-M4)/data!$E$14))) -> 0 | N7: =IF(M5=M4,"",IF(M5>M4,"List to Port","List to Starboard")) | Q7: App. Trim | R7: =V6-R6 -> 0.04 | T7: =ABS(DEGREES(ATAN((T5-T4)/data!$E$14))) -> 0 | U7: =IF(T5=T4,"",IF(T5>T4,"List to Port","List to Starboard"))
B9: Correction to Draft
B10: Draft correction | D10: =-D7*data!O8/data!P8 -> -0.0098128167 | F10: =(D7*data!O9)/207.5 -> 0 | H10: =D7*data!O10/data!P8 -> 0.07513814 | K10: =IF(O15=1,-data!$O$8*K7/data!$P$8,IF(O15=2,-data!$O$13*K7/data!$P$13,"")) -> 0.00062939349 | M10: =IF(O15=1,data!$O$9*K7/data!$P$8,IF(O15=2,data!$O$14*K7/data!$P$13,"")) -> -0.00021579205 | O10: =IF(O15=1,data!$O$10*K7/data!$P$8,IF(O15=2,data!$O$15*K7/data!$P$13,"")) -> -0.0048193559 | R10: =IF(V15=1,-data!$O$8*R7/data!$P$8,IF(V15=2,-data!$O$13*R7/data!$P$13,"")) -> -0.00022887036 | T10: =IF(V15=1,data!$O$9*R7/data!$P$8,IF(V15=2,data!$O$14*R7/data!$P$13,"")) -> 7.8469838e-05 | V10: =IF(V15=1,data!$O$10*R7/data!$P$8,IF(V15=2,data!$O$15*R7/data!$P$13,"")) -> 0.0017524931
B11: Corrected Draft | C11: dFP= | D11: =D6+D10 -> 8.1051872 | E11: dØ= | F11: =F6+F10 -> 9.13 | G11: dAP= | H11: =H6+H10 -> 9.9051381 | J11: dFP= | K11: =K6+K10 -> 17.780629 | L11: dØ= | M11: =M6+M10 -> 17.739784 | N11: dAP= | O11: =O6+O10 -> 17.665181 | Q11: dFP= | R11: =R6+R10 -> 18.039771 | S11: dØ= | T11: =T6+T10 -> 18.050078 | U11: dAP= | V11: =V6+V10 -> 18.081752
B12: Mean Draft | E12: dM= | F12: =(D11+H11)/2 -> 9.0051627 | L12: dM= | M12: =(K11+O11)/2 -> 17.722905 | S12: dM= | T12: =(R11+V11)/2 -> 18.060762
B13: True Trim | C13: T= | D13: =H11-D11 -> 1.799951 | E13: =IF(D13>0,"m by the stern","m by the head") -> m by the stern | G13: =ABS(F11-F12)*100 -> 12.483734 | H13: =IF(F11>F12,"cm SAG","cm HOG") -> cm SAG | J13: T= | K13: =O11-K11 -> -0.11544875 | L13: =IF(K13>0,"m by the stern","m by the head") -> m by the head | N13: =ABS(M11-M12)*100 -> 1.6879189 | O13: =IF(M11>M12,"cm SAG","cm HOG") -> cm SAG | Q13: T= | R13: =V11-R11 -> 0.041981363 | S13: =IF(R13>0,"m by the stern","m by the head") -> m by the stern | U13: =ABS(T11-T12)*100 -> 1.0683342 | V13: =IF(T11>T12,"cm SAG","cm HOG") -> cm HOG
B15: Correction by deflection | O15: =interim!H1 -> 2 | V15: =final!H1 -> 2
B16: Mid Mean | C16: dØ | F16: =F11 -> 9.13 | J16: dØ | M16: =M11 -> 17.739784 | Q16: dØ | T16: =T11 -> 18.050078
B17: Mean Draft | C17: dM | F17: =F12 -> 9.0051627 | J17: dM | M17: =M12 -> 17.722905 | Q17: dM | T17: =T12 -> 18.060762
B18: Mean of Mean | C18: Av=(dØ+dM)/2 | F18: =SUM(F16:F17)/2 -> 9.0675813 | J18: Av=(dØ+dM)/2 | M18: =SUM(M16:M17)/2 -> 17.731345 | Q18: Av=(dØ+dM)/2 | T18: =SUM(T16:T17)/2 -> 18.05542
B19: Quarter Mean | C19: dAv=(dØx3+dM)/4 | E19: dAv= | F19: =((F16*3)+F17)/4 -> 9.0987907 | J19: dAv=(dØx3+dM)/4 | L19: dAv= | M19: =((M16*3)+M17)/4 -> 17.735564 | Q19: dAv=(dØx3+dM)/4 | S19: dAv= | T19: =((T16*3)+T17)/4 -> 18.052749
B20: Correction by trim | J20: Correction by trim | Q20: Correction by trim
B21: Displacement at dAv | F21: =D43 -> 135863.34 | H21: 1st corr | I21: =(((D13*100)*E43)*F43)/data!$E$13 -> -1093.3648 | J21: Displacement at dAv | M21: =D49 -> 279028.91 | O21: 1st corr | P21: =(((K13*100)*E49)*F49)/data!$E$13 -> 1.5164616 | Q21: Displacement at dAv | T21: =D55 -> 284522.2 | V21: 1st corr | W21: =(((R13*100)*E55)*F55)/data!$E$13 -> 0.34177128
B22: Corr. displ due to trim | F22: =I23 -> -1052.3371 | H22: 2nd corr | I22: =(((D13*D13)*50)*I43)/data!$E$13 -> 41.027671 | J22: Corr. displ due to trim | M22: =P23 -> 1.7423388 | O22: 2nd corr | P22: =(((K13*K13)*50)*J49)/data!$E$13 -> 0.22587717 | Q22: Corr. displ due to trim | T22: =W23 -> 0.36867449 | V22: 2nd corr | W22: =(((R13*R13)*50)*J55)/data!$E$13 -> 0.026903211
B23: Corrected Displacement | F23: =SUM(F21:F22) -> 134811 | H23: total | I23: =SUM(I21:I22) -> -1052.3371 | J23: Corrected Displacement | M23: =SUM(M21:M22) -> 279030.65 | O23: total | P23: =SUM(P21:P22) -> 1.7423388 | Q23: Corrected Displacement | T23: =SUM(T21:T22) -> 284522.57 | V23: total | W23: =SUM(W21:W22) -> 0.36867449
B24: Correction for density | J24: Correction for density | Q24: Correction for density
B25: Actual sea water density | E25: p= | F25: =initial!I5 -> 1.023 | J25: Actual sea water density | L25: p= | M25: =interim!I5 -> 1.023 | Q25: Actual sea water density | S25: p= | T25: =final!I5 -> 1.023
B26: Resultant displacement | F26: =ROUND(F23*F25/1.025,0) -> 134548 | J26: Resultant displacement | M26: =ROUND(M23*M25/1.025,0) -> 278486 | Q26: Resultant displacement | T26: =T23*T25/1.025 -> 283967.4
B27: LIGHT SHIP | F27: =data!$E$12 -> 33323 | J27: LIGHT SHIP | M27: =data!$E$12 -> 33323 | Q27: LIGHT SHIP | T27: =data!$E$12 -> 33323
B28: DEAD WEIGHT | F28: =F26-F27 -> 101225 | J28: DEAD WEIGHT | M28: =M26-M27 -> 245163 | Q28: DEAD WEIGHT | T28: =T26-T27 -> 250644.4
B29: Known weights | J29: Known weights | Q29: Known weights
B30: Bunker (F.O. & D.O.) | F30: =ROUND(initial!I7+initial!I8,0) -> 1361 | J30: Bunker (F.O. & D.O.) | M30: =ROUND(interim!I7+interim!I8,0) -> 1350 | Q30: Bunker (F.O. & D.O.) | T30: =ROUND(final!I7+final!I8,0) -> 1350
B31: Fresh Water | F31: =ROUND(initial!I9,0) -> 215 | H31: req ballast | J31: Fresh Water | M31: =ROUND(interim!I9,0) -> 202 | Q31: Fresh Water | T31: =ROUND(final!I9,0) -> 202
B32: Ballast water | F32: =ROUND(initial!I10,0) -> 99020 | H32: =(F26-F27)-SUM(F30+F31+F33,initial!I15) -> 99020 | J32: Ballast water | M32: =ROUND(interim!I10,0) -> 31 | Q32: Ballast water | T32: =ROUND(final!I10,0) -> 31
B33: Others | F33: =ROUND(initial!I11,0) -> 0 | J33: Others | M33: =ROUND(interim!I11,0) -> 0 | Q33: Others | T33: =ROUND(final!I11,0) -> 0
B34: =IF(initial!C4=1,"","Constant") | F34: =initial!I12 -> 0 | J34: Constant | M34: =interim!I12 -> 629 | Q34: Constant | T34: =ROUND(final!I12,0) -> 629
B35: TOTAL WEIGHT | F35: =SUM(F30:F34) -> 100596 | J35: TOTAL WEIGHT | M35: =SUM(M30:M34) -> 2212 | Q35: TOTAL WEIGHT | T35: =SUM(T30:T34) -> 2212
D36: =IF(initial!C4=1,"Constant","CARGO") -> Constant | F36: =(F26-F27)-F35 -> 629 | L36: CARGO | M36: =(M26-M27)-M35 -> 242951 | S36: CARGO | T36: =(T26-T27)-T35 -> 248432.4
C40: initial
C41: DRAFT | D41: DISP | E41: TPC | F41: LCF | G41: MCTC | H41: MTC+/- | I41: MTC ~
C42: =VLOOKUP(F19,hydro!$B$3:$F$78,1) -> 9 | D42: =VLOOKUP(C42,hydro!$B$3:$F$78,2) -> 134298 | E42: =VLOOKUP(C42,hydro!$B$3:$F$78,3) -> 158.3 | F42: =VLOOKUP(C42,hydro!$B$3:$F$78,4) -> -12.4 | G42: =VLOOKUP(C42,hydro!$B$3:$F$78,5) -> 3109.1 | H42: =IF((F19+0.5-VLOOKUP(F19+0.5,hydro!$B$3:$F$78,1))>0.1,VLOOKUP(F19+0.6,hydro!$B$3:$F$78,1),VLOOKUP(F19+0.5,hydro!$B$3:$F$78,1)) -> 9.6 | I42: =VLOOKUP(H42,hydro!$B$3:$F$78,5) -> 3159.5
C43: =calc!F19 -> 9.0987907 | D43: =(D44-D42)/(C44-C42)*(C43-C42)+D42 -> 135863.34 | E43: =(E44-E42)/(C44-C42)*(C43-C42)+E42 -> 158.44819 | F43: =(F44-F42)/(C44-C42)*(C43-C42)+F42 -> -12.306149 | G43: =(G44-G42)/(C44-C42)*(C43-C42)+G42 -> 3117.1514 | H43: Diff | I43: =I42-I44 -> 81.3
C44: =C42+0.200000001 -> 9.2 | D44: =VLOOKUP(C44,hydro!$B$3:$F$78,2) -> 137467 | E44: =VLOOKUP(C44,hydro!$B$3:$F$78,3) -> 158.6 | F44: =VLOOKUP(C44,hydro!$B$3:$F$78,4) -> -12.21 | G44: =VLOOKUP(C44,hydro!$B$3:$F$78,5) -> 3125.4 | H44: =H42-1+0.0001 -> 8.6001 | I44: =VLOOKUP(H44,hydro!$B$3:$F$78,5) -> 3078.2
C46: intermediate
C47: DRAFT | D47: DISP | E47: TPC | F47: LCF | G47: LCB | H47: MCTC | I47: MTC+/- | J47: MTC ~
...

Sheet data
C2: SHIP'S NAME | E2: WARRAMBOO
C4: SHIP DATA | H4: TANK DATA | M4: DRAFT MARK DISTANCES TO PERPENDICULARS
C6: Port of Registry | E6: TOKYO | H6: Tanks | J6: LCG
C7: Gross Tonage | E7: 132512 | H7: 1 FOT PORT | J7: 106.32 | M7: Initial Survey | P7: LBDM
C8: Net Tonage | E8: 45968 | H8: 1 FOT STBD | J8: 106.32 | N8: For'd | O8: 1.75 | P8: =E13-(O8+O10) -> 305.85
C9: Summer Draught (m) | E9: 18.025 | H9: 2 FOT PORT | J9: 128.36 | N9: Mid | O9: 0
C10: Summer Displacement | E10: 284041 | H10: 2 FOT STBD | J10: 126.76 | N10: Aft | O10: 13.4
C11: Summer Deadweight | E11: 250718 | H11: 1 FO SETT (S) | J11: 119.1
C12: Light Ship | E12: 33323 | H12: 2 FO SETT (S) | J12: 122.3 | M12: Final Survey | P12: LBDM
C13: LBP (m) | E13: 321 | H13: 1 FO SERV (S) | J13: 125.5 | N13: For'd | O13: 1.75 | P13: =E13-(O13+O15) -> 305.85
C14: BEAM (m) | E14: 57 | H14: 2 FO SERV (S) | J14: 128.7 | N14: Mid | O14: 0.6
C15: LOA (m) | E15: 329.95 | H15: 1 DOT STBD | J15: 140.62 | N15: Aft | O15: 13.4
C16: FWA (mm) | E16: 409 | H16: 2 DOT STBD | J16: 144.78
H17: FWT PORT | J17: 153.27
H18: DWT STBD | J18: 153.27
B19: LOAD LINE WATER MARK | C19: FREEBOARD | D19: DRAFT | E19: DISPLACEMENT | F19: DEADWEIGHT | H19: APT '(C) | J19: 155.1 | M19: HATCH DATA
H20: LO SUMP '(C) | J20: 131.57 | M20: Hatch | N20: LCG | O20: CAPACITY (m3) | Q20: MAXIMUM LOAD WEIGHT
B21: TF | C21: 6.354 | D21: 18.809 | E21: 290417 | F21: 257094 | H21: 1 WBT P | J21: -123.28
H22: 1 WBT S | J22: -123.28 | M22: 1 | N22: -121.07 | O22: 21838.9 | Q22: 39210
B23: F | C23: 6.729 | D23: 18.434 | E23: 284044 | F23: 250721 | H23: 2 WBT P | J23: -76.49 | M23: 2 | N23: -88.9 | O23: 17761 | Q23: 27962
H24: 2 WBT S | J24: -76.49 | M24: 3 | N24: -64.15 | O24: 17761 | Q24: 27962
B25: T | C25: 6.763 | D25: 18.4 | E25: 290553 | F25: 257230 | H25: 3 WBT P | J25: -22.08 | M25: 4 | N25: -34.45 | O25: 17754 | Q25: 27951
H26: 3 WBT S | J26: -22.08 | M26: 5 | N26: -9.7 | O26: 17754 | Q26: 27951
B27: S | C27: 7.138 | D27: 18.025 | E27: 284041 | F27: 250718 | H27: 4 WBT P | J27: 32.35 | M27: 6 | N27: 20 | O27: 17760 | Q27: 27961
H28: 4 WBT S | J28: 32.35 | M28: 7 | N28: 44.75 | O28: 17760 | Q28: 27961
B29: W | C29: 7.513 | D29: 17.65 | E29: 277549 | F29: 244226 | H29: 5 WBT P | J29: 84.21 | M29: 8 | N29: 74.45 | O29: 18188 | Q29: 28637
H30: 5 WBT S | J30: 84.21 | M30: 9 | N30: 99.2 | O30: 18188 | Q30: 28637
H31: DWST (P) | J31: 105.55 | M31: TOTAL | O31: =SUM(O22:O30) -> 164764.9
H32: DWST (S) | J32: 105.55

Sheet hydro
B2: Draft | C2: Disp | D2: TPC | E2: LCF | F2: MCTC | G2: LCB
B3: 6 | C3: 87474 | D3: 153.8 | E3: -14.35 | F3: 2892 | G3: -15.19
B4: 6.2 | C4: 90554 | D4: 154.2 | E4: -14.27 | F4: 2906 | G4: -15.16
B5: 6.4 | C5: 93640 | D5: 154.5 | E5: -14.17 | F5: 2920.4 | G5: -15.12
B6: 6.6 | C6: 96732 | D6: 154.8 | E6: -14.07 | F6: 2934.9 | G6: -15.09
B7: 6.8 | C7: 99830 | D7: 155.1 | E7: -13.96 | F7: 2949.5 | G7: -15.05
B8: 7 | C8: 102934 | D8: 155.4 | E8: -13.84 | F8: 2964 | G8: -15.01
B9: 7.2 | C9: 106044 | D9: 155.7 | E9: -13.72 | F9: 2978.3 | G9: -14.97
B10: 7.4 | C10: 109160 | D10: 156 | E10: -13.6 | F10: 2992.4 | G10: -14.93
B11: 7.6 | C11: 112282 | D11: 156.3 | E11: -13.48 | F11: 3006.4 | G11: -14.89
B12: 7.8 | C12: 115410 | D12: 156.6 | E12: -13.34 | F12: 3020.4 | G12: -14.85
B13: 8 | C13: 118544 | D13: 156.9 | E13: -13.21 | F13: 3034.5 | G13: -14.8
B14: 8.2 | C14: 121683 | D14: 157.1 | E14: -13.06 | F14: 3048.8 | G14: -14.76
... B77: 20.8 | C77: 332577 | D77: 176 | E77: 1.93 | F77: 4234.7 | G77: -8.46
B78: 21
